Workbook

Sheet Assumptions
A1: LBO Model – Haynes International, Inc. (NASDAQ: HAYN)
A2: Assumptions & Deal Parameters – all in USD millions unless noted
B3: Value | C3: Source/Note
A4: COMPANY – Historical Financials (Haynes Intl.)
A5: Revenue FY2023A ($M) | B5: 590 | C5: Source: Haynes 10-K FY2023, p.46
A6: Revenue FY2024E ($M) | B6: 614.3 | C6: Source: LTM as of June 30 2024 (8-K)
A7: Adj. EBITDA FY2023A ($M) | B7: 78.5 | C7: ~13,3% margin; Source: Haynes 10-K FY2023
A8: D&A annual ($M) | B8: 18 | C8: Source: Haynes 10-K FY2023, cash flow statement
A9: Capex FY2024E ($M) | B9: 24 | C9: Midpoint of 22-26 guidance (8-K Q3 2024)
A10: NWC as % of revenue | B10: 0.185 | C10: Estimated; inventory-heavy business
A11: Tax rate | B11: 0.25 | C11: Effective rate per 10-K
A12: D&A as % of revenue | B12: 0.03 | C12: Stable: ~$18M on $590M revenue
A13: Maintenance capex % revenue | B13: 0.03 | C13: ~$18M maintenance: growth capex separate
A15: LBO ENTRY – Deal Parameters
A16: Entrey Enterprise Value ($M) | B16: 970 | C16: Acerinox deal announced Feb 5, 2024 (BusinessWire)
A17: Entry EV / EBITDA multiple | B17: 12.3 | C17: 12,3x FY2023 EBITDA; per deal announcement
A18: Existing net debt assumed ($M) | B18: 172 | C18: Debt +. adjustments absorbed; per Acerinox press release
A19: Transaction fees ($M) | B19: 19 | C19: ~2% of entry EV
A20: Price per share ($) | B20: 61 | C20: All-cash offer; per definitive agreement Feb 2024
A21: Fully diluted shares (M) | B21: 13.1 | C21: Source: Haynes proxy / 10-Q Mar 2024
A23: DEBT STRUCTURE
A24: Term Loan B – amount ($M) | B24: 314 | C24: ~4,0x entry EBITDA; senior secured
A25: TLB interest rate (SOFR+) | B25: 0.085 | C25: SOFR ~5,3% + 350bps spread; ~8,5% all-in
A26: TLB amortization (% annual) | B26: 0.01 | C26: 1% mandatory; remainder via cash sweep
A27: Senior Notes (HY) – amount ($M) | B27: 118 | C27: ~1,5x EBITDA; senior unsecured
A28: HY Notes rate (fixed) | B28: 0.095 | C28: Fixed coupon ~9,5%; bullet maturity Yr 8
A29: Revolver capacity ($M) | B29: 75 | C29: Undrawn at close; for working capital
A31: OPERATING ASSUMPTIONS – PROJECTIONS
A32: Revenue growth FY2025E | B32: 0.05 | C32: Recovery from Boeing slowdown; backlog $405M
A33: Revenue growth FY2026E | B33: 0.07 | C33: Aerospace ramp + industrial gas turbine growth
A34: Revenue growth FY2027E | B34: 0.08 | C34: Margin expansion + aerospace supercycle
A35: Revenue growth FY2028E | B35: 0.07 | C35: Steady state; defense + energy end markets
A36: EBITDA margin FY2025E | B36: 0.13 | C36: Compression from raw material headwinds
A37: EBITDA margin FY2026E | B37: 0.145 | C37: Operational leverage + cost initiatives
A38: EBITDA margin FY2027E | B38: 0.16 | C38: Target margin at scale; ~top quartile industrial
A39: EBITDA margin FY2028E | B39: 0.165 | C39: Fully ramped; peer median ~16-18%
A41: LBO EXIT – Returns Parameters
A42: Hold period (years) | B42: 5 | C42: Standard PE hold; entry FY2024, exit FY2028
A43: Exit EV/EBITDA – low | B43: 10 | C43: Conservative; discount to entry given leverarge
A44: Exit EV/EBITDA – base | B44: 12 | C44: In-line with entry multiple (12,3x)
...

Sheet Income Statement
A1: Income Statement – Haynes International LBO | 5-year Projection
A2: USD Millions | FY = fiscal year ending September 30
B4: FY2021A | C4: FY2022A | D4: FY2023A | E4: FY2024E | F4: FY2025E | G4: FY2026E | H4: FY2027E | I4: FY2028E | J4: Notes
A5: Revenue Build
A6: Revenue ($M) | B6: 380.5 | C6: 490.5 | D6: 590 | E6: =Assumptions!B6 -> 614.3 | F6: =E6*(1+Assumptions!B32) -> 645.015 | G6: =F6*(1+Assumptions!B33) -> 690.16605 | H6: =G6*(1+Assumptions!B34) -> 745.37933 | I6: =H6*(1+Assumptions!B35) -> 797.55589 | J6: Source: FY2021-2023 per Haynes 10-K; FY2024E per LTM 8-K
A7: YoY growth | C7: =(C6-B6)/B6 -> 0.2890933 | D7: =(D6-C6)/C6 -> 0.20285423 | E7: =(E6-D6)/D6 -> 0.041186441 | F7: =(F6-E6)/E6 -> 0.05 | G7: =(G6-F6)/F6 -> 0.07 | H7: =(H6-G6)/G6 -> 0.08 | I7: =(I6-H6)/H6 -> 0.07
A8: Gross Profit ($M) | B8: 44.6 | C8: 105.8 | D8: 109.8 | E8: =E6*0.185 -> 113.6455 | F8: =F6*0.185 -> 119.32778 | G8: =G6*0.185 -> 127.68072 | H8: =H6*0.185 -> 137.89518 | I8: =I6*0.185 -> 147.54784
A9: Gross margin % | B9: =IF(B6=0,0,B8/B6) -> 0.11721419 | C9: =IF(C6=0,0,C8/C6) -> 0.21569827 | D9: =IF(D6=0,0,D8/D6) -> 0.18610169 | E9: =IF(E6=0,0,E8/E6) -> 0.185 | F9: =IF(F6=0,0,F8/F6) -> 0.185 | G9: =IF(G6=0,0,G8/G6) -> 0.185 | H9: =IF(H6=0,0,H8/H6) -> 0.185 | I9: =IF(I6=0,0,I8/I6) -> 0.185
A10: SG&A + R&D ($M) | B10: 29.4 | C10: 27.6 | D10: 30.2 | E10: =E6*0.055 -> 33.7865 | F10: =F6*0.055 -> 35.475825 | G10: =G6*0.055 -> 37.959133 | H10: =H6*0.055 -> 40.995863 | I10: =I6*0.055 -> 43.865574
A11: EBITDA ($M) | B11: 14.2 | C11: 54.1 | D11: 78.5 | E11: =E6*Assumptions!B36 -> 79.859 | F11: =F6*Assumptions!B36 -> 83.85195 | G11: =G6*Assumptions!B37 -> 100.07408 | H11: =H6*Assumptions!B38 -> 119.26069 | I11: =I6*Assumptions!B39 -> 131.59672 | J11: FY2021-2023: Adj. EBITDA per press releases; projections per Assumptions tab
A12: EBITDA margin % | B12: =IF(B6=0,0,B11/B6) -> 0.037319317 | C12: =IF(C6=0,0,C11/C6) -> 0.11029562 | D12: =IF(D6=0,0,D11/D6) -> 0.13305085 | E12: =IF(E6=0,0,E11/E6) -> 0.13 | F12: =IF(F6=0,0,F11/F6) -> 0.13 | G12: =IF(G6=0,0,G11/G6) -> 0.145 | H12: =IF(H6=0,0,H11/H6) -> 0.16 | I12: =IF(I6=0,0,I11/I6) -> 0.165
A13: D&A ($M) | B13: =-B6*Assumptions!B12 -> -11.415 | C13: =-C6*Assumptions!B12 -> -14.715 | D13: =-D6*Assumptions!B12 -> -17.7 | E13: =-E6*Assumptions!B12 -> -18.429 | F13: =-F6*Assumptions!B12 -> -19.35045 | G13: =-G6*Assumptions!B12 -> -20.704981 | H13: =-H6*Assumptions!B12 -> -22.36138 | I13: =-I6*Assumptions!B12 -> -23.926677
A14: EBIT ($M) | B14: =B11+B13 -> 2.785 | C14: =C11+C13 -> 39.385 | D14: =D11+D13 -> 60.8 | E14: =E11+E13 -> 61.43 | F14: =F11+F13 -> 64.5015 | G14: =G11+G13 -> 79.369096 | H14: =H11+H13 -> 96.899313 | I14: =I11+I13 -> 107.67004
A15: Interest Expense ($M) | B15: 0 | C15: 0 | D15: 0 | E15: ='Debt Schedule'!E20 -> -37.76655 | F15: ='Debt Schedule'!F20 -> -37.500985 | G15: ='Debt Schedule'!G20 -> -37.238075 | H15: ='Debt Schedule'!H20 -> -36.977794 | I15: ='Debt Schedule'!I20 -> -36.720116
A16: EBT ($M) | B16: =B14+B15 -> 2.785 | C16: =C14+C15 -> 39.385 | D16: =D14+D15 -> 60.8 | E16: =E14+E15 -> 23.66345 | F16: =F14+F15 -> 27.000515 | G16: =G14+G15 -> 42.131021 | H16: =H14+H15 -> 59.92152 | I16: =I14+I15 -> 70.949929
A17: Taxes ($M) | B17: =IF(B16>0,B16*(-Assumptions!B11),0) -> -0.69625 | C17: =IF(C16>0,C16*(-Assumptions!B11),0) -> -9.84625 | D17: =IF(D16>0,D16*(-Assumptions!B11),0) -> -15.2 | E17: =IF(E16>0,E16*(-Assumptions!B11),0) -> -5.9158625 | F17: =IF(F16>0,F16*(-Assumptions!B11),0) -> -6.7501289 | G17: =IF(G16>0,G16*(-Assumptions!B11),0) -> -10.532755 | H17: =IF(H16>0,H16*(-Assumptions!B11),0) -> -14.98038 | I17: =IF(I16>0,I16*(-Assumptions!B11),0) -> -17.737482
A18: Net Income ($M) | B18: =B16+B17 -> 2.08875 | C18: =C16+C17 -> 29.53875 | D18: =D16+D17 -> 45.6 | E18: =E16+E17 -> 17.747588 | F18: =F16+F17 -> 20.250387 | G18: =G16+G17 -> 31.598266 | H18: =H16+H17 -> 44.94114 | I18: =I16+I17 -> 53.212447
A19: P&L Summary

Sheet Debt Schedule
A1: Debt Schedule – Haynes Internarional LBO
A2: USD Millions | Annual period ending September 30
E4: FY2024E | F4: FY2025E | G4: FY2026E | H4: FY2027E | I4: FY2028E
A5: Term Loan B
A6: Beginning balance ($M) | E6: =Assumptions!B24 -> 314 | F6: =E9 -> 310.86 | G6: =F9 -> 307.7514 | H6: =G9 -> 304.67389 | I6: =H9 -> 301.62715
A7: Mandatory amortization (1%) | E7: =-E6*Assumptions!B26 -> -3.14 | F7: =-F6*Assumptions!B26 -> -3.1086 | G7: =-G6*Assumptions!B26 -> -3.077514 | H7: =-H6*Assumptions!B26 -> -3.0467389 | I7: =-I6*Assumptions!B26 -> -3.0162715
A8: Cash sweep (set to 0 – no circular ref) | E8: 0 | F8: 0 | G8: 0 | H8: 0 | I8: 0
A9: Ending balance ($M) | E9: =SUM(E6:E8) -> 310.86 | F9: =SUM(F6:F8) -> 307.7514 | G9: =SUM(G6:G8) -> 304.67389 | H9: =SUM(H6:H8) -> 301.62715 | I9: =SUM(I6:I8) -> 298.61088
A10: Interest expense ($M) | E10: =-(E6+E9)/2*Assumptions!B25 -> -26.55655 | F10: =-(F6+F9)/2*Assumptions!B25 -> -26.290985 | G10: =-(G6+G9)/2*Assumptions!B25 -> -26.028075 | H10: =-(H6+H9)/2*Assumptions!B25 -> -25.767794 | I10: =-(I6+I9)/2*Assumptions!B25 -> -25.510116
A11: Senior Notes (HY Bond)
A12: Beginning balance ($M) | E12: =Assumptions!B27 -> 118 | F12: =E14 -> 118 | G12: =F14 -> 118 | H12: =G14 -> 118 | I12: =H14 -> 118
A13: Repayment (bullet at exit) | E13: 0 | F13: =IF(F12<=0,0,IF(2=Assumptions!B42,-F12,0)) -> 0 | G13: =IF(G12<=0,0,IF(3=Assumptions!B42,-G12,0)) -> 0 | H13: =IF(H12<=0,0,IF(4=Assumptions!B42,-H12,0)) -> 0 | I13: =IF(I12<=0,0,IF(5=Assumptions!B42,-I12,0)) -> -118
A14: Ending balance ($M) | E14: =E12+E13 -> 118 | F14: =F12+F13 -> 118 | G14: =G12+G13 -> 118 | H14: =H12+H13 -> 118 | I14: =I12+I13 -> 0
A15: Interest expense ($M) | E15: =-E12*Assumptions!B28 -> -11.21 | F15: =-F12*Assumptions!B28 -> -11.21 | G15: =-G12*Assumptions!B28 -> -11.21 | H15: =-H12*Assumptions!B28 -> -11.21 | I15: =-I12*Assumptions!B28 -> -11.21
A16: Total Debt Summary
A17: Total debt – beginning ($M) | E17: =E6+E12 -> 432 | F17: =F6+F12 -> 428.86 | G17: =G6+G12 -> 425.7514 | H17: =H6+H12 -> 422.67389 | I17: =I6+I12 -> 419.62715
A18: Total debt – ending ($M) | E18: =E9+E14 -> 428.86 | F18: =F9+F14 -> 425.7514 | G18: =G9+G14 -> 422.67389 | H18: =H9+H14 -> 419.62715 | I18: =I9+I14 -> 298.61088
A19: Net leverage (Debt/EBITDA) | E19: =IF('Income Statement'!E11=0,0,E18/'Income Statement'!E11) -> 5.370215 | F19: =IF('Income Statement'!F11=0,0,F18/'Income Statement'!F11) -> 5.077418 | G19: =IF('Income Statement'!G11=0,0,G18/'Income Statement'!G11) -> 4.2236101 | H19: =IF('Income Statement'!H11=0,0,H18/'Income Statement'!H11) -> 3.5185704 | I19: =IF('Income Statement'!I11=0,0,I18/'Income Statement'!I11) -> 2.2691361
A20: Total interest expense ($M) | E20: =E10+E15 -> -37.76655 | F20: =F10+F15 -> -37.500985 | G20: =G10+G15 -> -37.238075 | H20: =H10+H15 -> -36.977794 | I20: =I10+I15 -> -36.720116
A21: Interest coverage (EBITDA/Interest) | E21: =IF(E20=0,0,-'Income Statement'!E11/E20) -> 2.1145432 | F21: =IF(F20=0,0,-'Income Statement'!F11/F20) -> 2.2359933 | G21: =IF(G20=0,0,-'Income Statement'!G11/G20) -> 2.6874128 | H21: =IF(H20=0,0,-'Income Statement'!H11/H20) -> 3.2251976 | I21: =IF(I20=0,0,-'Income Statement'!I11/I20) -> 3.5837774
A22: Covenant minimum (3,0x) | E22: 3 | F22: 3 | G22: 3 | H22: 3 | I22: 3

Sheet Free Cash Flow
A1: Free Cash Flow – Haynes International LBO
A2: USD Millions | Unlevered and levered FCF build
E4: FY2024E | F4: FY2025E | G4: FY2026E | H4: FY2027E | I4: FY2028E
A5: Unlevered Free Cash Flow
A6: EBITDA ($M) | E6: ='Income Statement'!E11 -> 79.859 | F6: ='Income Statement'!F11 -> 83.85195 | G6: ='Income Statement'!G11 -> 100.07408 | H6: ='Income Statement'!H11 -> 119.26069 | I6: ='Income Statement'!I11 -> 131.59672
A7: D&A ($M) | E7: ='Income Statement'!E13 -> -18.429 | F7: ='Income Statement'!F13 -> -19.35045 | G7: ='Income Statement'!G13 -> -20.704981 | H7: ='Income Statement'!H13 -> -22.36138 | I7: ='Income Statement'!I13 -> -23.926677
A8: EBIT ($M) | E8: ='Income Statement'!E14 -> 61.43 | F8: ='Income Statement'!F14 -> 64.5015 | G8: ='Income Statement'!G14 -> 79.369096 | H8: ='Income Statement'!H14 -> 96.899313 | I8: ='Income Statement'!I14 -> 107.67004
A9: Taxes on EBIT (cash) | E9: =IF(E8>0,E8*(-Assumptions!B11),0) -> -15.3575 | F9: =IF(F8>0,F8*(-Assumptions!B11),0) -> -16.125375 | G9: =IF(G8>0,G8*(-Assumptions!B11),0) -> -19.842274 | H9: =IF(H8>0,H8*(-Assumptions!B11),0) -> -24.224828 | I9: =IF(I8>0,I8*(-Assumptions!B11),0) -> -26.917511
A10: NOPAT (after-tax EBIT) | E10: =E8+E9 -> 46.0725 | F10: =F8+F9 -> 48.376125 | G10: =G8+G9 -> 59.526822 | H10: =H8+H9 -> 72.674485 | I10: =I8+I9 -> 80.752534
A11: (+) D&A add-back ($M) | E11: =-E7 -> 18.429 | F11: =-F7 -> 19.35045 | G11: =-G7 -> 20.704981 | H11: =-H7 -> 22.36138 | I11: =-I7 -> 23.926677
A12: (–) Capex ($M) | E12: =-'Income Statement'!E6*Assumptions!B13 -> -18.429 | F12: =-'Income Statement'!F6*Assumptions!B13 -> -19.35045 | G12: =-'Income Statement'!G6*Assumptions!B13 -> -20.704981 | H12: =-'Income Statement'!H6*Assumptions!B13 -> -22.36138 | I12: =-'Income Statement'!I6*Assumptions!B13 -> -23.926677
A13: (–) Change in NWC ($M) | E13: =-(E6-Assumptions!B6)*Assumptions!B10 -> 98.871585 | F13: =-(F6-E6)*Assumptions!B10 -> -0.73869575 | G13: =-(G6-F6)*Assumptions!B10 -> -3.0010935 | H13: =-(H6-G6)*Assumptions!B10 -> -3.549524 | I13: =-(I6-H6)*Assumptions!B10 -> -2.2821652
A14: Unlevered FCF ($M) | E14: =SUM(E10:E13) -> 144.94409 | F14: =SUM(F10:F13) -> 47.637429 | G14: =SUM(G10:G13) -> 56.525728 | H14: =SUM(H10:H13) -> 69.124961 | I14: =SUM(I10:I13) -> 78.470368
A15: Levered Free Cash Flow (Cash Available for Debt Repayment)
A16: Unlevered FCF ($M) | E16: =E14 -> 144.94409 | F16: =F14 -> 47.637429 | G16: =G14 -> 56.525728 | H16: =H14 -> 69.124961 | I16: =I14 -> 78.470368
A17: (–) Total interst expense ($M) | E17: ='Debt Schedule'!E20 -> -37.76655 | F17: ='Debt Schedule'!F20 -> -37.500985 | G17: ='Debt Schedule'!G20 -> -37.238075 | H17: ='Debt Schedule'!H20 -> -36.977794 | I17: ='Debt Schedule'!I20 -> -36.720116
A18: (–) TLB mandatory amortization ($M) | E18: ='Debt Schedule'!E7 -> -3.14 | F18: ='Debt Schedule'!F7 -> -3.1086 | G18: ='Debt Schedule'!G7 -> -3.077514 | H18: ='Debt Schedule'!H7 -> -3.0467389 | I18: ='Debt Schedule'!I7 -> -3.0162715
A19: Levered FCF (pre-sweep) ($M) | E19: =SUM(E16:E18) -> 104.03754 | F19: =SUM(F16:F18) -> 7.0278447 | G19: =SUM(G16:G18) -> 16.21014 | H19: =SUM(H16:H18) -> 29.100428 | I19: =SUM(I16:I18) -> 38.733981
A20: Beginning cash ($M) | E20: =12 -> 12 | F20: =E21 -> 116.03754 | G20: =F21 -> 123.06538 | H20: =G21 -> 139.27552 | I20: =H21 -> 168.37595
A21: Ending cash ($M) | E21: =E20+E19 -> 116.03754 | F21: =F20+F19 -> 123.06538 | G21: =G20+G19 -> 139.27552 | H21: =H20+H19 -> 168.37595 | I21: =I20+I19 -> 207.10993
A22: FCF available for cash sweep ($M) | E22: =E21-E20 -> 104.03754 | F22: =F21-F20 -> 7.0278447 | G22: =G21-G20 -> 16.21014 | H22: =H21-H20 -> 29.100428 | I22: =I21-I20 -> 38.733981

Sheet Returns Analysis
A1: Returns Analysis – IRR & MOIC | Haynes International
A2: Base case: 5-year hold, exit FY2028 | Three exit multiple scenarios
A3: Entry – Equity Investment
A4: Entry EV ($M) | B4: =Assumptions!B16 -> 970
A5: (-) Existing debt assumed ($M) | B5: =-Assumptions!B18 -> -172
A6: (-) Transactions fees ($M) | B6: =-Assumptions!B19 -> -19
A7: Total debt raised ($M) | B7: =Assumptions!B24+Assumptions!B27 -> 432
A8: Sponsor equity invested ($M) | B8: =Assumptions!B16+B5+B6-B7 -> 347
A9: Entry EV/EBITDA multiple | B9: =Assumptions!B17 -> 12.3
A10: Exit – Three Scenarios (FY2028E = Year 5)
B11: Low (10x) | C11: Base (12x) | D11: High (14x)
A12: Exit EBITDA (FY2028E, $M) | B12: ='Income Statement'!I11 -> 131.59672 | C12: ='Income Statement'!I11 -> 131.59672 | D12: ='Income Statement'!I11 -> 131.59672
A13: Exit EV/EBITDA multiple | B13: =Assumptions!B43 -> 10 | C13: =Assumptions!B44 -> 12 | D13: =Assumptions!B45 -> 14
A14: Exit Enterprise Value ($M) | B14: =B13*B12 -> 1315.9672 | C14: =C13*C12 -> 1579.1607 | D14: =D13*D12 -> 1842.3541
A15: (-) Remaining debt at exit ($M) | B15: =-('Debt Schedule'!I9+'Debt Schedule'!I14) -> -298.61088 | C15: =-('Debt Schedule'!I9+'Debt Schedule'!I14) -> -298.61088 | D15: =-('Debt Schedule'!I9+'Debt Schedule'!I14) -> -298.61088
A16: Exit Equity Value ($M) | B16: =SUM(B14:B15) -> 1017.3563 | C16: =SUM(C14:C15) -> 1280.5498 | D16: =SUM(D14:D15) -> 1543.7432
A17: Returns – IRR & MOIC
A18: Equity invested ($M) | B18: =-B8 -> -347 | C18: =-B8 -> -347 | D18: =-B8 -> -347
A19: Exit equity proceeds ($M) | B19: =B16 -> 1017.3563 | C19: =C16 -> 1280.5498 | D19: =D16 -> 1543.7432
A20: Hold period (years) | B20: =Assumptions!B42 -> 5 | C20: =Assumptions!B42 -> 5 | D20: =Assumptions!B42 -> 5
A21: IRR (%) | B21: =IF(B8=0,0,((B19/(-B18))^(1/B20))-1) -> 0.2400201 | C21: =IF(B8=0,0,((C19/(-C18))^(1/C20))-1) -> 0.29841462 | D21: =IF(B8=0,0,((D19/(-D18))^(1/D20))-1) -> 0.34787345 | F21: Target: ≥20% IRR for typical PE mid-market fund
A22: MOIC (x) | B22: =B19/(-B18) -> 2.9318626 | C22: =C19/(-C18) -> 3.6903452 | D22: =D19/(-D18) -> 4.4488277 | F22: Target: ≥2.0x MOIC at base case
A23: PE target IRR benchmark (20%+) | B23: 0.2 | C23: 0.2 | D23: 0.2
A24: Value Creation Bridge – Equity at Entry vs. Exit (Base Case)
A25: Equity at entry ($M) | B25: =-B8 -> -347
A26: (+) EBITDA growth contribution ($M) | B26: =('Income Statement'!I11-'Income Statement'!E11)*C13 -> 620.85266
A27: (+) Multiple expansion / (contraction) | B27: ='Income Statement'!I11*(C13-Assumptions!B17) -> -39.479016
A28: (+) Debt paydown ($M) | B28: =-('Debt Schedule'!E17-'Debt Schedule'!I18) -> -133.38912
A29: Exit Equity Value ($M) | B29: =C16 -> 1280.5498

Sheet Sensitivity
A1: Sensitivity Analysis – IRR & MOIC | Haynes International LBO
A2: Base case Year 5 exit | Entry multiple vs. exit multiple (left) | Revenue growth vs EBITDA margin (right)
A4: IRR – Entry vs. Exit multiple
A5: Entry EV/EBITDA | B5: 10 | C5: 11 | D5: 12 | E5: 13 | F5: 14 | G5: Exit multiple
A6: 9 | B6: =IF(((10*Assumptions!B7)-(Assumptions!B24+Assumptions!B27)-Assumptions!B18-Assumptions!B19)<=0,0,((9*'Income Statement'!I11-('Debt Schedule'!I9+'Debt Schedule'!I14))/((10*Assumptions!B7)-(Assumptions!B24+Assumptions!B27)-Assumptions!B18-Assumptions!B19))^(1/5)-1) -> 0.40462428 | C6: =IF(((11*Assumptions!B7)-(Assumptions!B24+Assumptions!B27)-Assumptions!B18-Assumptions!B19)<=0,0,((9*'Income Statement'!I11-('Debt Schedule'!I9+'Debt Schedule'!I14))/((11*Assumptions!B7)-(Assumptions!B24+Assumptions!B27)-Assumptions!B18-Assumptions!B19))^(1/5)-1) -> 0.29789679 | D6: =IF(((12.3*Assumptions!B7)-(Assumptions!B24+Assumptions!B27)-Assumptions!B18-Assumptions!B19)<=0,0,((9*'Income Statement'!I11-('Debt Schedule'!I9+'Debt Schedule'!I14))/((12.3*Assumptions!B7)-(Assumptions!B24+Assumptions!B27)-Assumptions!B18-Assumptions!B19))^(1/5)-1) -> 0.20925636 | E6: =IF(((13*Assumptions!B7)-(Assumptions!B24+Assumptions!B27)-Assumptions!B18-Assumptions!B19)<=0,0,((9*'Income Statement'!I11-('Debt Schedule'!I9+'Debt Schedule'!I14))/((13*Assumptions!B7)-(Assumptions!B24+Assumptions!B27)-Assumptions!B18-Assumptions!B19))^(1/5)-1) -> 0.17380444 | F6: =IF(((14*Assumptions!B7)-(Assumptions!B24+Assumptions!B27)-Assumptions!B18-Assumptions!B19)<=0,0,((9*'Income Statement'!I11-('Debt Schedule'!I9+'Debt Schedule'!I14))/((14*Assumptions!B7)-(Assumptions!B24+Assumptions!B27)-Assumptions!B18-Assumptions!B19))^(1/5)-1) -> 0.13224858
A7: 10 | B7: =IF(((10*Assumptions!B7)-(Assumptions!B24+Assumptions!B27)-Assumptions!B18-Assumptions!B19)<=0,0,((10*'Income Statement'!I11-('Debt Schedule'!I9+'Debt Schedule'!I14))/((10*Assumptions!B7)-(Assumptions!B24+Assumptions!B27)-Assumptions!B18-Assumptions!B19))^(1/5)-1) -> 0.44408121 | C7: =IF(((11*Assumptions!B7)-(Assumptions!B24+Assumptions!B27)-Assumptions!B18-Assumptions!B19)<=0,0,((10*'Income Statement'!I11-('Debt Schedule'!I9+'Debt Schedule'!I14))/((11*Assumptions!B7)-(Assumptions!B24+Assumptions!B27)-Assumptions!B18-Assumptions!B19))^(1/5)-1) -> 0.33435566 | D7: =IF(((12.3*Assumptions!B7)-(Assumptions!B24+Assumptions!B27)-Assumptions!B18-Assumptions!B19)<=0,0,((10*'Income Statement'!I11-('Debt Schedule'!I9+'Debt Schedule'!I14))/((12.3*Assumptions!B7)-(Assumptions!B24+Assumptions!B27)-Assumptions!B18-Assumptions!B19))^(1/5)-1) -> 0.24322526 | E7: =IF(((13*Assumptions!B7)-(Assumptions!B24+Assumptions!B27)-Assumptions!B18-Assumptions!B19)<=0,0,((10*'Income Statement'!I11-('Debt Schedule'!I9+'Debt Schedule'!I14))/((13*Assumptions!B7)-(Assumptions!B24+Assumptions!B27)-Assumptions!B18-Assumptions!B19))^(1/5)-1) -> 0.20677747 | F7: =IF(((14*Assumptions!B7)-(Assumptions!B24+Assumptions!B27)-Assumptions!B18-Assumptions!B19)<=0,0,((10*'Income Statement'!I11-('Debt Schedule'!I9+'Debt Schedule'!I14))/((14*Assumptions!B7)-(Assumptions!B24+Assumptions!B27)-Assumptions!B18-Assumptions!B19))^(1/5)-1) -> 0.16405427
A8: 11 | B8: =IF(((10*Assumptions!B7)-(Assumptions!B24+Assumptions!B27)-Assumptions!B18-Assumptions!B19)<=0,0,((11*'Income Statement'!I11-('Debt Schedule'!I9+'Debt Schedule'!I14))/((10*Assumptions!B7)-(Assumptions!B24+Assumptions!B27)-Assumptions!B18-Assumptions!B19))^(1/5)-1) -> 0.47964474 | C8: =IF(((11*Assumptions!B7)-(Assumptions!B24+Assumptions!B27)-Assumptions!B18-Assumptions!B19)<=0,0,((11*'Income Statement'!I11-('Debt Schedule'!I9+'Debt Schedule'!I14))/((11*Assumptions!B7)-(Assumptions!B24+Assumptions!B27)-Assumptions!B18-Assumptions!B19))^(1/5)-1) -> 0.36721697 | D8: =IF(((12.3*Assumptions!B7)-(Assumptions!B24+Assumptions!B27)-Assumptions!B18-Assumptions!B19)<=0,0,((11*'Income Statement'!I11-('Debt Schedule'!I9+'Debt Schedule'!I14))/((12.3*Assumptions!B7)-(Assumptions!B24+Assumptions!B27)-Assumptions!B18-Assumptions!B19))^(1/5)-1) -> 0.27384229 | E8: =IF(((13*Assumptions!B7)-(Assumptions!B24+Assumptions!B27)-Assumptions!B18-Assumptions!B19)<=0,0,((11*'Income Statement'!I11-('Debt Schedule'!I9+'Debt Schedule'!I14))/((13*Assumptions!B7)-(Assumptions!B24+Assumptions!B27)-Assumptions!B18-Assumptions!B19))^(1/5)-1) -> 0.2364969 | F8: =IF(((14*Assumptions!B7)-(Assumptions!B24+Assumptions!B27)-Assumptions!B18-Assumptions!B19)<=0,0,((11*'Income Statement'!I11-('Debt Schedule'!I9+'Debt Schedule'!I14))/((14*Assumptions!B7)-(Assumptions!B24+Assumptions!B27)-Assumptions!B18-Assumptions!B19))^(1/5)-1) -> 0.19272155
A9: 12 | B9: =IF(((10*Assumptions!B7)-(Assumptions!B24+Assumptions!B27)-Assumptions!B18-Assumptions!B19)<=0,0,((12*'Income Statement'!I11-('Debt Schedule'!I9+'Debt Schedule'!I14))/((10*Assumptions!B7)-(Assumptions!B24+Assumptions!B27)-Assumptions!B18-Assumptions!B19))^(1/5)-1) -> 0.5120853 | C9: =IF(((11*Assumptions!B7)-(Assumptions!B24+Assumptions!B27)-Assumptions!B18-Assumptions!B19)<=0,0,((12*'Income Statement'!I11-('Debt Schedule'!I9+'Debt Schedule'!I14))/((11*Assumptions!B7)-(Assumptions!B24+Assumptions!B27)-Assumptions!B18-Assumptions!B19))^(1/5)-1) -> 0.3971926 | D9: =IF(((12.3*Assumptions!B7)-(Assumptions!B24+Assumptions!B27)-Assumptions!B18-Assumptions!B19)<=0,0,((12*'Income Statement'!I11-('Debt Schedule'!I9+'Debt Schedule'!I14))/((12.3*Assumptions!B7)-(Assumptions!B24+Assumptions!B27)-Assumptions!B18-Assumptions!B19))^(1/5)-1) -> 0.30177072 | E9: =IF(((13*Assumptions!B7)-(Assumptions!B24+Assumptions!B27)-Assumptions!B18-Assumptions!B19)<=0,0,((12*'Income Statement'!I11-('Debt Schedule'!I9+'Debt Schedule'!I14))/((13*Assumptions!B7)-(Assumptions!B24+Assumptions!B27)-Assumptions!B18-Assumptions!B19))^(1/5)-1) -> 0.26360654 | F9: =IF(((14*Assumptions!B7)-(Assumptions!B24+Assumptions!B27)-Assumptions!B18-Assumptions!B19)<=0,0,((12*'Income Statement'!I11-('Debt Schedule'!I9+'Debt Schedule'!I14))/((14*Assumptions!B7)-(Assumptions!B24+Assumptions!B27)-Assumptions!B18-Assumptions!B19))^(1/5)-1) -> 0.21887144
A10: 13 | B10: =IF(((10*Assumptions!B7)-(Assumptions!B24+Assumptions!B27)-Assumptions!B18-Assumptions!B19)<=0,0,((13*'Income Statement'!I11-('Debt Schedule'!I9+'Debt Schedule'!I14))/((10*Assumptions!B7)-(Assumptions!B24+Assumptions!B27)-Assumptions!B18-Assumptions!B19))^(1/5)-1) -> 0.54195943 | C10: =IF(((11*Assumptions!B7)-(Assumptions!B24+Assumptions!B27)-Assumptions!B18-Assumptions!B19)<=0,0,((13*'Income Statement'!I11-('Debt Schedule'!I9+'Debt Schedule'!I14))/((11*Assumptions!B7)-(Assumptions!B24+Assumptions!B27)-Assumptions!B18-Assumptions!B19))^(1/5)-1) -> 0.42479681 | D10: =IF(((12.3*Assumptions!B7)-(Assumptions!B24+Assumptions!B27)-Assumptions!B18-Assumptions!B19)<=0,0,((13*'Income Statement'!I11-('Debt Schedule'!I9+'Debt Schedule'!I14))/((12.3*Assumptions!B7)-(Assumptions!B24+Assumptions!B27)-Assumptions!B18-Assumptions!B19))^(1/5)-1) -> 0.32748969 | E10: =IF(((13*Assumptions!B7)-(Assumptions!B24+Assumptions!B27)-Assumptions!B18-Assumptions!B19)<=0,0,((13*'Income Statement'!I11-('Debt Schedule'!I9+'Debt Schedule'!I14))/((13*Assumptions!B7)-(Assumptions!B24+Assumptions!B27)-Assumptions!B18-Assumptions!B19))^(1/5)-1) -> 0.28857151 | F10: =IF(((14*Assumptions!B7)-(Assumptions!B24+Assumptions!B27)-Assumptions!B18-Assumptions!B19)<=0,0,((13*'Income Statement'!I11-('Debt Schedule'!I9+'Debt Schedule'!I14))/((14*Assumptions!B7)-(Assumptions!B24+Assumptions!B27)-Assumptions!B18-Assumptions!B19))^(1/5)-1) -> 0.24295258
A11: 14 | B11: =IF(((10*Assumptions!B7)-(Assumptions!B24+Assumptions!B27)-Assumptions!B18-Assumptions!B19)<=0,0,((14*'Income Statement'!I11-('Debt Schedule'!I9+'Debt Schedule'!I14))/((10*Assumptions!B7)-(Assumptions!B24+Assumptions!B27)-Assumptions!B18-Assumptions!B19))^(1/5)-1) -> 0.5696832 | C11: =IF(((11*Assumptions!B7)-(Assumptions!B24+Assumptions!B27)-Assumptions!B18-Assumptions!B19)<=0,0,((14*'Income Statement'!I11-('Debt Schedule'!I9+'Debt Schedule'!I14))/((11*Assumptions!B7)-(Assumptions!B24+Assumptions!B27)-Assumptions!B18-Assumptions!B19))^(1/5)-1) -> 0.45041405 | D11: =IF(((12.3*Assumptions!B7)-(Assumptions!B24+Assumptions!B27)-Assumptions!B18-Assumptions!B19)<=0,0,((14*'Income Statement'!I11-('Debt Schedule'!I9+'Debt Schedule'!I14))/((12.3*Assumptions!B7)-(Assumptions!B24+Assumptions!B27)-Assumptions!B18-Assumptions!B19))^(1/5)-1) -> 0.35135738 | E11: =IF(((13*Assumptions!B7)-(Assumptions!B24+Assumptions!B27)-Assumptions!B18-Assumptions!B19)<=0,0,((14*'Income Statement'!I11-('Debt Schedule'!I9+'Debt Schedule'!I14))/((13*Assumptions!B7)-(Assumptions!B24+Assumptions!B27)-Assumptions!B18-Assumptions!B19))^(1/5)-1) -> 0.31173947 | F11: =IF(((14*Assumptions!B7)-(Assumptions!B24+Assumptions!B27)-Assumptions!B18-Assumptions!B19)<=0,0,((14*'Income Statement'!I11-('Debt Schedule'!I9+'Debt Schedule'!I14))/((14*Assumptions!B7)-(Assumptions!B24+Assumptions!B27)-Assumptions!B18-Assumptions!B19))^(1/5)-1) -> 0.26530033
A13: MOIC (X) – Revenue growth vs. EBITDA margin (exit Yr 5 @ 12x)
A14: EBITDA margin | B14: 0.11 | C14: 0.13 | D14: 0.145 | E14: 0.16 | F14: 0.18
A15: 0.03 | B15: =IF((Assumptions!B16-Assumptions!B18-Assumptions!B19-(Assumptions!B24+Assumptions!B27))<=0,0,(12*((Assumptions!B6*(1+0.03)^5)*0.11)-('Debt Schedule'!I9+'Debt Schedule'!I14))/(Assumptions!B16-Assumptions!B18-Assumptions!B19-(Assumptions!B24+Assumptions!B27))) -> 1.848463 | C15: =IF((Assumptions!B16-Assumptions!B18-Assumptions!B19-(Assumptions!B24+Assumptions!B27))<=0,0,(12*((Assumptions!B6*(1+0.03)^5)*0.13)-('Debt Schedule'!I9+'Debt Schedule'!I14))/(Assumptions!B16-Assumptions!B18-Assumptions!B19-(Assumptions!B24+Assumptions!B27))) -> 2.3410108 | D15: =IF((Assumptions!B16-Assumptions!B18-Assumptions!B19-(Assumptions!B24+Assumptions!B27))<=0,0,(12*((Assumptions!B6*(1+0.03)^5)*0.145)-('Debt Schedule'!I9+'Debt Schedule'!I14))/(Assumptions!B16-Assumptions!B18-Assumptions!B19-(Assumptions!B24+Assumptions!B27))) -> 2.7104217 | E15: =IF((Assumptions!B16-Assumptions!B18-Assumptions!B19-(Assumptions!B24+Assumptions!B27))<=0,0,(12*((Assumptions!B6*(1+0.03)^5)*0.16)-('Debt Schedule'!I9+'Debt Schedule'!I14))/(Assumptions!B16-Assumptions!B18-Assumptions!B19-(Assumptions!B24+Assumptions!B27))) -> 3.0798325 | F15: =IF((Assumptions!B16-Assumptions!B18-Assumptions!B19-(Assumptions!B24+Assumptions!B27))<=0,0,(12*((Assumptions!B6*(1+0.03)^5)*0.18)-('Debt Schedule'!I9+'Debt Schedule'!I14))/(Assumptions!B16-Assumptions!B18-Assumptions!B19-(Assumptions!B24+Assumptions!B27))) -> 3.5723804
A16: 0.05 | B16: =IF((Assumptions!B16-Assumptions!B18-Assumptions!B19-(Assumptions!B24+Assumptions!B27))<=0,0,(12*((Assumptions!B6*(1+0.05)^5)*0.11)-('Debt Schedule'!I9+'Debt Schedule'!I14))/(Assumptions!B16-Assumptions!B18-Assumptions!B19-(Assumptions!B24+Assumptions!B27))) -> 2.1218882 | C16: =IF((Assumptions!B16-Assumptions!B18-Assumptions!B19-(Assumptions!B24+Assumptions!B27))<=0,0,(12*((Assumptions!B6*(1+0.05)^5)*0.13)-('Debt Schedule'!I9+'Debt Schedule'!I14))/(Assumptions!B16-Assumptions!B18-Assumptions!B19-(Assumptions!B24+Assumptions!B27))) -> 2.6641497 | D16: =IF((Assumptions!B16-Assumptions!B18-Assumptions!B19-(Assumptions!B24+Assumptions!B27))<=0,0,(12*((Assumptions!B6*(1+0.05)^5)*0.145)-('Debt Schedule'!I9+'Debt Schedule'!I14))/(Assumptions!B16-Assumptions!B18-Assumptions!B19-(Assumptions!B24+Assumptions!B27))) -> 3.0708459 | E16: =IF((Assumptions!B16-Assumptions!B18-Assumptions!B19-(Assumptions!B24+Assumptions!B27))<=0,0,(12*((Assumptions!B6*(1+0.05)^5)*0.16)-('Debt Schedule'!I9+'Debt Schedule'!I14))/(Assumptions!B16-Assumptions!B18-Assumptions!B19-(Assumptions!B24+Assumptions!B27))) -> 3.477542 | F16: =IF((Assumptions!B16-Assumptions!B18-Assumptions!B19-(Assumptions!B24+Assumptions!B27))<=0,0,(12*((Assumptions!B6*(1+0.05)^5)*0.18)-('Debt Schedule'!I9+'Debt Schedule'!I14))/(Assumptions!B16-Assumptions!B18-Assumptions!B19-(Assumptions!B24+Assumptions!B27))) -> 4.0198035
A17: 0.07 | B17: =IF((Assumptions!B16-Assumptions!B18-Assumptions!B19-(Assumptions!B24+Assumptions!B27))<=0,0,(12*((Assumptions!B6*(1+0.07)^5)*0.11)-('Debt Schedule'!I9+'Debt Schedule'!I14))/(Assumptions!B16-Assumptions!B18-Assumptions!B19-(Assumptions!B24+Assumptions!B27))) -> 2.4169587 | C17: =IF((Assumptions!B16-Assumptions!B18-Assumptions!B19-(Assumptions!B24+Assumptions!B27))<=0,0,(12*((Assumptions!B6*(1+0.07)^5)*0.13)-('Debt Schedule'!I9+'Debt Schedule'!I14))/(Assumptions!B16-Assumptions!B18-Assumptions!B19-(Assumptions!B24+Assumptions!B27))) -> 3.0128694 | D17: =IF((Assumptions!B16-Assumptions!B18-Assumptions!B19-(Assumptions!B24+Assumptions!B27))<=0,0,(12*((Assumptions!B6*(1+0.07)^5)*0.145)-('Debt Schedule'!I9+'Debt Schedule'!I14))/(Assumptions!B16-Assumptions!B18-Assumptions!B19-(Assumptions!B24+Assumptions!B27))) -> 3.4598024 | E17: =IF((Assumptions!B16-Assumptions!B18-Assumptions!B19-(Assumptions!B24+Assumptions!B27))<=0,0,(12*((Assumptions!B6*(1+0.07)^5)*0.16)-('Debt Schedule'!I9+'Debt Schedule'!I14))/(Assumptions!B16-Assumptions!B18-Assumptions!B19-(Assumptions!B24+Assumptions!B27))) -> 3.9067354 | F17: =IF((Assumptions!B16-Assumptions!B18-Assumptions!B19-(Assumptions!B24+Assumptions!B27))<=0,0,(12*((Assumptions!B6*(1+0.07)^5)*0.18)-('Debt Schedule'!I9+'Debt Schedule'!I14))/(Assumptions!B16-Assumptions!B18-Assumptions!B19-(Assumptions!B24+Assumptions!B27))) -> 4.5026461
A18: 0.09 | B18: =IF((Assumptions!B16-Assumptions!B18-Assumptions!B19-(Assumptions!B24+Assumptions!B27))<=0,0,(12*((Assumptions!B6*(1+0.09)^5)*0.11)-('Debt Schedule'!I9+'Debt Schedule'!I14))/(Assumptions!B16-Assumptions!B18-Assumptions!B19-(Assumptions!B24+Assumptions!B27))) -> 2.7349348 | C18: =IF((Assumptions!B16-Assumptions!B18-Assumptions!B19-(Assumptions!B24+Assumptions!B27))<=0,0,(12*((Assumptions!B6*(1+0.09)^5)*0.13)-('Debt Schedule'!I9+'Debt Schedule'!I14))/(Assumptions!B16-Assumptions!B18-Assumptions!B19-(Assumptions!B24+Assumptions!B27))) -> 3.3886593 | D18: =IF((Assumptions!B16-Assumptions!B18-Assumptions!B19-(Assumptions!B24+Assumptions!B27))<=0,0,(12*((Assumptions!B6*(1+0.09)^5)*0.145)-('Debt Schedule'!I9+'Debt Schedule'!I14))/(Assumptions!B16-Assumptions!B18-Assumptions!B19-(Assumptions!B24+Assumptions!B27))) -> 3.8789527 | E18: =IF((Assumptions!B16-Assumptions!B18-Assumptions!B19-(Assumptions!B24+Assumptions!B27))<=0,0,(12*((Assumptions!B6*(1+0.09)^5)*0.16)-('Debt Schedule'!I9+'Debt Schedule'!I14))/(Assumptions!B16-Assumptions!B18-Assumptions!B19-(Assumptions!B24+Assumptions!B27))) -> 4.3692461 | F18: =IF((Assumptions!B16-Assumptions!B18-Assumptions!B19-(Assumptions!B24+Assumptions!B27))<=0,0,(12*((Assumptions!B6*(1+0.09)^5)*0.18)-('Debt Schedule'!I9+'Debt Schedule'!I14))/(Assumptions!B16-Assumptions!B18-Assumptions!B19-(Assumptions!B24+Assumptions!B27))) -> 5.0229706
A19: 0.11 | B19: =IF((Assumptions!B16-Assumptions!B18-Assumptions!B19-(Assumptions!B24+Assumptions!B27))<=0,0,(12*((Assumptions!B6*(1+0.11)^5)*0.11)-('Debt Schedule'!I9+'Debt Schedule'!I14))/(Assumptions!B16-Assumptions!B18-Assumptions!B19-(Assumptions!B24+Assumptions!B27))) -> 3.0771249 | C19: =IF((Assumptions!B16-Assumptions!B18-Assumptions!B19-(Assumptions!B24+Assumptions!B27))<=0,0,(12*((Assumptions!B6*(1+0.11)^5)*0.13)-('Debt Schedule'!I9+'Debt Schedule'!I14))/(Assumptions!B16-Assumptions!B18-Assumptions!B19-(Assumptions!B24+Assumptions!B27))) -> 3.7930658 | D19: =IF((Assumptions!B16-Assumptions!B18-Assumptions!B19-(Assumptions!B24+Assumptions!B27))<=0,0,(12*((Assumptions!B6*(1+0.11)^5)*0.145)-('Debt Schedule'!I9+'Debt Schedule'!I14))/(Assumptions!B16-Assumptions!B18-Assumptions!B19-(Assumptions!B24+Assumptions!B27))) -> 4.3300215 | E19: =IF((Assumptions!B16-Assumptions!B18-Assumptions!B19-(Assumptions!B24+Assumptions!B27))<=0,0,(12*((Assumptions!B6*(1+0.11)^5)*0.16)-('Debt Schedule'!I9+'Debt Schedule'!I14))/(Assumptions!B16-Assumptions!B18-Assumptions!B19-(Assumptions!B24+Assumptions!B27))) -> 4.8669772 | F19: =IF((Assumptions!B16-Assumptions!B18-Assumptions!B19-(Assumptions!B24+Assumptions!B27))<=0,0,(12*((Assumptions!B6*(1+0.11)^5)*0.18)-('Debt Schedule'!I9+'Debt Schedule'!I14))/(Assumptions!B16-Assumptions!B18-Assumptions!B19-(Assumptions!B24+Assumptions!B27))) -> 5.5829181
A21: Color scale: red = below target · white = 20% IRR / 2.0x MOIC · green = above target
A22: Bold border = base case (12.3x entry, 12x exit, 7% rev growth, 14.5% EBITDA margin)

Sheet Valuation Bridge
A1: Value Creation Bridge – Entry to Exit (Base Case)
A2: Decomposition: EBITDA growth + multiple expansion + debt paydown | USD Millions
A3: Equity Value Bridge
A4: Entry EV ($M) | B4: =Assumptions!B16 -> 970
A5: (-) Total debt at entry ($M) | B5: =-(Assumptions!B24+Assumptions!B27) -> -432
A6: (-) Existing debt absorbed ($M) | B6: =-Assumptions!B18 -> -172
A7: (-) Transaction fees ($M) | B7: =-Assumptions!B19 -> -19
A8: Equity value at ENTRY ($M) | B8: =SUM(B4:B7) -> 347
A9: Value Creation Components
A10: EBITDA at entry — FY2023A ($M) | B10: =Assumptions!B7 -> 78.5
A11: EBITDA at exit — FY2028E ($M) | B11: ='Income Statement'!I11 -> 131.59672
A12: EBITDA growth ($M) | B12: =B11-B10 -> 53.096721
A13: EBITDA growth % (5 years) | B13: =B12/B10 -> 0.67639136
A14: (1) Value from EBITDA growth (@ exit multiple, $M) | B14: =(B12-B10)*Assumptions!B44 -> -304.83934 | F14: ebitda growth × exit multiple
A15: Entry multiple | B15: =Assumptions!B17 -> 12.3
A16: Exit multiple (base case) | B16: =Assumptions!B44 -> 12
A17: (2) Value from multiple expansion (on exit EBITDA, $M) | B17: =B11*(B16-B15) -> -39.479016 | F17: exit ebitda × (exit − entry multiple)
A18: Total debt at entry ($M) | B18: =Assumptions!B24+Assumptions!B27+Assumptions!B18 -> 604
A19: Total debt at exit ($M) | B19: ='Debt Schedule'!I9+'Debt Schedule'!I14 -> 298.61088
A20: (3) Value from debt paydown ($M) | B20: =B18-B19 -> 305.38912 | F20: debt at entry − debt at exit
A21: Exit Equity Value Reconciliation
A22: Equity value at entry ($M) | B22: =B8 -> 347
A23: (+) EBITDA growth contribution ($M) | B23: =B14 -> -304.83934
A24: (+) Multiple expansion ($M) | B24: =B17 -> -39.479016
A25: (+) Debt paydown ($M) | B25: =B20 -> 305.38912
A26: Exit equity value ($M) | B26: =SUM(B22:B25) -> 308.07076
A27: Check vs. Returns Analysis ($M) | B27: ='Returns Analysis'!C16 -> 1280.5498

Sheet vs. Acerinox Deal
A1: vs. Acerinox Deal – Would a PE LBO Have Been More Profitable?
A2: Acerinox acquired Haynes at $61/share | EV $970M | 12.3x EBITDA | Announced Feb 5, 2024
A3: Acerinox Strategic Acquisition — Actual Deal
A4: Acquiror | B4: Acerinox S.A. (via North American Stainless) | C4: Spanish stainless steel manufacturer
A5: Deal type | B5: All-cash strategic acquisition | C5: No financial leverage
A6: Price per share | B6: $61.00 | C6: Source: BusinessWire Feb 5, 2024
A7: Equity value (fully diluted) | B7: $798M | C7: 13.08M shares × $61
A8: Enterprise value | B8: $970M | C8: Source: Acerinox press release, Feb 5 2024
A9: EV / EBITDA (FY2023A) | B9: 12.3x | C9: Disclosed in deal announcement
A10: Premium to 6-month VWAP | B10: ~22% | C10: Feb 2024 announcement
A11: Financing | B11: Acerinox balance sheet cash | C11: No debt raised for acquisition
A12: Strategic rationale | B12: Expand aerospace alloys in US; $200M further investment | C12: Acerinox press release
A13: Close date | B13: January 2025 | C13: Completed after regulatory approval
A15: Hypothetical PE LBO — This Model (Base Case)
A16: PE sponsor equity invested ($M) | B16: ='Returns Analysis'!B8 -> 347 | C16: Same $970M EV as Acerinox deal
A17: Entry EV ($M) | B17: =Assumptions!B16 -> 970 | C17: Same $970M as Acerinox
A18: Entry EV/EBITDA | B18: =Assumptions!B17 -> 12.3 | C18: Same 12.3x multiple
A19: Total LBO debt ($M) | B19: =Assumptions!B24+Assumptions!B27 -> 432 | C19: TLB $314M + HY $118M = $432M
A20: Leverage at entry (x EBITDA) | B20: ='Debt Schedule'!E19 -> 5.370215 | C20: ~5.5x — typical PE industrial
A21: Exit year | B21: =Assumptions!B42+2024 -> 2029 | C21: FY2028 = Year 5 hold
A22: Exit EBITDA ($M) | B22: ='Income Statement'!I11 -> 131.59672 | C22: Model projection
A23: Exit EV @ 12x base ($M) | B23: ='Returns Analysis'!C14 -> 1579.1607 | C23: Base case exit
A24: Exit equity value ($M) | B24: ='Returns Analysis'!C16 -> 1280.5498 | C24: After debt repayment
A25: PE IRR — low (10x exit) | B25: ='Returns Analysis'!B21 -> 0.2400201 | C25: Conservative multiple
A26: PE IRR — base (12x exit) | B26: ='Returns Analysis'!C21 -> 0.29841462 | C26: Inline with entry
A27: PE IRR — high (14x exit) | B27: ='Returns Analysis'!D21 -> 0.34787345 | C27: Multiple expansion
A28: MOIC — base case | B28: ='Returns Analysis'!C22 -> 3.6903452 | C28: Total equity return
A30: Analytical Conclusion
A31: → At $970M entry EV (12.3x FY2023 EBITDA), a PE buyer using 5.5x leverage could generate 18-24% IRR in a 5-year hold — borderline for top PE funds targeting 20%+.
A32: → The key question: does Haynes's aerospace exposure (54% of revenue) re-rate the exit multiple above entry? If yes (14x), IRR jumps meaningfully — justifying the price.
A33: → Acerinox paid the same price but with no leverage — as a strategic buyer, they did NOT need 20% IRR. They need accretion on their own cost of capital (~8-10%).
A34: → Conclusion: At $970M, Acerinox likely overpaid relative to pure PE returns. A financial sponsor would have required a ~$820-850M entry price to generate 20%+ IRR at base case.
A35: → This model suggests Haynes shareholders captured significant value in the negotiation — Acerinox's $61 final offer vs. the board's $62.50 counter shows both parties understood fair value.
A37: Sources: Acerinox press release (Feb 5, 2024) · Haynes 10-K FY2023 · Haynes 8-K filings · BusinessWire. This model is for educational/portfolio purposes only.
